# Japanese message translation file for plpython
# Copyright (C) 2022 PostgreSQL Global Development Group
# This file is distributed under the same license as the pg_archivecleanup (PostgreSQL) package.
# Honda Shigehiro <honda@postgresql.jp>, 2012.
#
msgid ""
msgstr ""
<<<<<<< HEAD
"Project-Id-Version: plpython (PostgreSQL) 10\n"
"Report-Msgid-Bugs-To: pgsql-bugs@postgresql.org\n"
"POT-Creation-Date: 2018-08-31 16:22+0900\n"
"PO-Revision-Date: 2018-08-21 20:45+0900\n"
"Last-Translator: Kyotaro Horiguchi <horiguchi.kyotaro@lab.ntt.co.jp>\n"
=======
"Project-Id-Version: plpython (PostgreSQL 15)\n"
"Report-Msgid-Bugs-To: pgsql-bugs@lists.postgresql.org\n"
"POT-Creation-Date: 2019-06-11 11:34+0900\n"
"PO-Revision-Date: 2021-08-25 17:42+0900\n"
"Last-Translator: Kyotaro Horiguchi <horikyota.ntt@gmail.com>\n"
>>>>>>> c1ff2d8bc5be55e302731a16aaff563b7f03ed7c
"Language-Team: Japan PostgreSQL Users Group <jpug-doc@ml.postgresql.jp>\n"
"Language: ja\n"
"MIME-Version: 1.0\n"
"Content-Type: text/plain; charset=UTF-8\n"
"Content-Transfer-Encoding: 8bit\n"
"Plural-Forms: nplurals=1; plural=0;\n"
<<<<<<< HEAD
"X-Generator: Poedit 1.5.4\n"

#: plpy_cursorobject.c:101
=======
"X-Generator: Poedit 1.8.13\n"

#: plpy_cursorobject.c:78
>>>>>>> c1ff2d8bc5be55e302731a16aaff563b7f03ed7c
#, c-format
msgid "plpy.cursor expected a query or a plan"
msgstr "plpy.cursor は問い合わせもしくは実行計画を期待していました"

<<<<<<< HEAD
#: plpy_cursorobject.c:184
=======
#: plpy_cursorobject.c:161
>>>>>>> c1ff2d8bc5be55e302731a16aaff563b7f03ed7c
#, c-format
msgid "plpy.cursor takes a sequence as its second argument"
msgstr "plpy.cursor は第二引数としてシーケンスを取ります"

<<<<<<< HEAD
#: plpy_cursorobject.c:200 plpy_spi.c:211
=======
#: plpy_cursorobject.c:177 plpy_spi.c:211
>>>>>>> c1ff2d8bc5be55e302731a16aaff563b7f03ed7c
#, c-format
msgid "could not execute plan"
msgstr "実行計画を実行できませんでした"

<<<<<<< HEAD
#: plpy_cursorobject.c:203 plpy_spi.c:214
=======
#: plpy_cursorobject.c:180 plpy_spi.c:214
>>>>>>> c1ff2d8bc5be55e302731a16aaff563b7f03ed7c
#, c-format
msgid "Expected sequence of %d argument, got %d: %s"
msgid_plural "Expected sequence of %d arguments, got %d: %s"
msgstr[0] "%d 個の引数のシーケンスを期待していましたが、個数は %d でした：%s"

<<<<<<< HEAD
#: plpy_cursorobject.c:352
=======
#: plpy_cursorobject.c:329
>>>>>>> c1ff2d8bc5be55e302731a16aaff563b7f03ed7c
#, c-format
msgid "iterating a closed cursor"
msgstr "反復利用しようとしているカーソルは、すでにクローズされています"

<<<<<<< HEAD
#: plpy_cursorobject.c:360 plpy_cursorobject.c:426
=======
#: plpy_cursorobject.c:337 plpy_cursorobject.c:403
>>>>>>> c1ff2d8bc5be55e302731a16aaff563b7f03ed7c
#, c-format
msgid "iterating a cursor in an aborted subtransaction"
msgstr "中断されたサブトランザクションの中でカーソルを反復利用しようとしています"

<<<<<<< HEAD
#: plpy_cursorobject.c:418
=======
#: plpy_cursorobject.c:395
>>>>>>> c1ff2d8bc5be55e302731a16aaff563b7f03ed7c
#, c-format
msgid "fetch from a closed cursor"
msgstr "クローズされたカーソルからのフェッチ"

<<<<<<< HEAD
#: plpy_cursorobject.c:461 plpy_spi.c:409
=======
#: plpy_cursorobject.c:438 plpy_spi.c:409
>>>>>>> c1ff2d8bc5be55e302731a16aaff563b7f03ed7c
#, c-format
msgid "query result has too many rows to fit in a Python list"
msgstr "問い合わせの結果に含まれる行数が、Pythonのリストに対して多すぎます"

<<<<<<< HEAD
#: plpy_cursorobject.c:512
=======
#: plpy_cursorobject.c:490
>>>>>>> c1ff2d8bc5be55e302731a16aaff563b7f03ed7c
#, c-format
msgid "closing a cursor in an aborted subtransaction"
msgstr "中断されたサブトランザクションの中でカーソルをクローズしようとしています"

<<<<<<< HEAD
#: plpy_elog.c:127 plpy_elog.c:128 plpy_plpymodule.c:559
=======
#: plpy_elog.c:129 plpy_elog.c:130 plpy_plpymodule.c:553
>>>>>>> c1ff2d8bc5be55e302731a16aaff563b7f03ed7c
#, c-format
msgid "%s"
msgstr "%s"

<<<<<<< HEAD
#: plpy_exec.c:142
=======
#: plpy_exec.c:143
>>>>>>> c1ff2d8bc5be55e302731a16aaff563b7f03ed7c
#, c-format
msgid "unsupported set function return mode"
msgstr "非サポートの集合関数リターンモードです。"

<<<<<<< HEAD
#: plpy_exec.c:143
#, c-format
msgid "PL/Python set-returning functions only support returning one value per call."
msgstr "PL/Python の集合を返す関数では、１回の呼び出しに対して１つの値を返すことのみがサポートされています。"

#: plpy_exec.c:156
=======
#: plpy_exec.c:144
#, c-format
msgid ""
"PL/Python set-returning functions only support returning one value per call."
msgstr ""
"集合を返却するPL/Python関数では、1回の呼び出しに対して1つの値を返すことのみが"
"サポートされています。"

#: plpy_exec.c:157
>>>>>>> c1ff2d8bc5be55e302731a16aaff563b7f03ed7c
#, c-format
msgid "returned object cannot be iterated"
msgstr "返されたオブジェクトは反復利用できません"

<<<<<<< HEAD
#: plpy_exec.c:157
#, c-format
msgid "PL/Python set-returning functions must return an iterable object."
msgstr "PL/Python の集合を返す関数は、イテレータ（反復利用可能）オブジェクトを返さなければなりません。"

#: plpy_exec.c:171
=======
#: plpy_exec.c:158
#, c-format
msgid "PL/Python set-returning functions must return an iterable object."
msgstr ""
"PL/Pythonの集合を返す関数は、反復処理可能なオブジェクトを返さなければなりませ"
"ん。"

#: plpy_exec.c:172
>>>>>>> c1ff2d8bc5be55e302731a16aaff563b7f03ed7c
#, c-format
msgid "error fetching next item from iterator"
msgstr "反復子から次の項目を取り出せませんでした"

<<<<<<< HEAD
#: plpy_exec.c:214
=======
#: plpy_exec.c:215
>>>>>>> c1ff2d8bc5be55e302731a16aaff563b7f03ed7c
#, c-format
msgid "PL/Python procedure did not return None"
msgstr "PL/Python プロシージャが None を返しませんでした"

<<<<<<< HEAD
#: plpy_exec.c:218
#, c-format
msgid "PL/Python function with return type \"void\" did not return None"
msgstr "戻り値が \"void\" 型である PL/Python 関数が None を返しませんでした"

#: plpy_exec.c:374 plpy_exec.c:400
=======
#: plpy_exec.c:219
#, c-format
msgid "PL/Python function with return type \"void\" did not return None"
msgstr "戻り値が\"void\"型である PL/Python関数がNoneを返しませんでした"

#: plpy_exec.c:375 plpy_exec.c:401
>>>>>>> c1ff2d8bc5be55e302731a16aaff563b7f03ed7c
#, c-format
msgid "unexpected return value from trigger procedure"
msgstr "トリガプロシージャから期待しない戻り値が返されました"

<<<<<<< HEAD
#: plpy_exec.c:375
=======
#: plpy_exec.c:376
>>>>>>> c1ff2d8bc5be55e302731a16aaff563b7f03ed7c
#, c-format
msgid "Expected None or a string."
msgstr "None もしくは文字列を期待していました。"

<<<<<<< HEAD
#: plpy_exec.c:390
#, c-format
msgid "PL/Python trigger function returned \"MODIFY\" in a DELETE trigger -- ignored"
msgstr "PL/Python トリガ関数が、DELETE トリガで \"MODIFY\" を返しました-- 無視されました"

#: plpy_exec.c:401
=======
#: plpy_exec.c:391
#, c-format
msgid ""
"PL/Python trigger function returned \"MODIFY\" in a DELETE trigger -- ignored"
msgstr ""
"PL/Python トリガ関数が、DELETE トリガで \"MODIFY\" を返しました-- 無視します"

#: plpy_exec.c:402
>>>>>>> c1ff2d8bc5be55e302731a16aaff563b7f03ed7c
#, c-format
msgid "Expected None, \"OK\", \"SKIP\", or \"MODIFY\"."
msgstr "None, \"OK\", \"SKIP\", \"MODIFY\" のいずれかを期待していました。"

<<<<<<< HEAD
#: plpy_exec.c:451
=======
#: plpy_exec.c:452
>>>>>>> c1ff2d8bc5be55e302731a16aaff563b7f03ed7c
#, c-format
msgid "PyList_SetItem() failed, while setting up arguments"
msgstr "引数を設定する際に、PyList_SetItem() に失敗しました"

<<<<<<< HEAD
#: plpy_exec.c:455
=======
#: plpy_exec.c:456
>>>>>>> c1ff2d8bc5be55e302731a16aaff563b7f03ed7c
#, c-format
msgid "PyDict_SetItemString() failed, while setting up arguments"
msgstr "引数を設定する際に、PyDict_SetItemString() に失敗しました"

<<<<<<< HEAD
#: plpy_exec.c:467
=======
#: plpy_exec.c:468
>>>>>>> c1ff2d8bc5be55e302731a16aaff563b7f03ed7c
#, c-format
msgid "function returning record called in context that cannot accept type record"
msgstr "レコード型を受け付けられないコンテキストでレコードを返す関数が呼び出されました"

<<<<<<< HEAD
#: plpy_exec.c:684
=======
#: plpy_exec.c:685
>>>>>>> c1ff2d8bc5be55e302731a16aaff563b7f03ed7c
#, c-format
msgid "while creating return value"
msgstr "戻り値を生成する際に"

<<<<<<< HEAD
#: plpy_exec.c:909
=======
#: plpy_exec.c:919
>>>>>>> c1ff2d8bc5be55e302731a16aaff563b7f03ed7c
#, c-format
msgid "TD[\"new\"] deleted, cannot modify row"
msgstr "TD[\"new\"] は削除されました。行を変更できません。"

<<<<<<< HEAD
#: plpy_exec.c:914
=======
#: plpy_exec.c:924
>>>>>>> c1ff2d8bc5be55e302731a16aaff563b7f03ed7c
#, c-format
msgid "TD[\"new\"] is not a dictionary"
msgstr "TD[\"new\"] は辞書ではありません"

<<<<<<< HEAD
#: plpy_exec.c:941
=======
#: plpy_exec.c:951
>>>>>>> c1ff2d8bc5be55e302731a16aaff563b7f03ed7c
#, c-format
msgid "TD[\"new\"] dictionary key at ordinal position %d is not a string"
msgstr "TD[\"new\"] 辞書の%d番目のキーが文字列ではありません"

<<<<<<< HEAD
#: plpy_exec.c:948
#, c-format
msgid "key \"%s\" found in TD[\"new\"] does not exist as a column in the triggering row"
msgstr "TD[\"new\"] で見つかったキー \"%s\" は、行レベルトリガにおけるカラムとしては存在しません"

#: plpy_exec.c:953
=======
#: plpy_exec.c:958
#, c-format
msgid ""
"key \"%s\" found in TD[\"new\"] does not exist as a column in the triggering "
"row"
msgstr ""
"TD[\"new\"] で見つかったキー \"%s\" は、行レベルトリガにおけるカラムとしては"
"存在しません"

#: plpy_exec.c:963
>>>>>>> c1ff2d8bc5be55e302731a16aaff563b7f03ed7c
#, c-format
msgid "cannot set system attribute \"%s\""
msgstr "システム属性\"%s\"は設定できません"

<<<<<<< HEAD
#: plpy_exec.c:1011
=======
#: plpy_exec.c:968
#, c-format
#| msgid "cannot alter inherited column \"%s\""
msgid "cannot set generated column \"%s\""
msgstr "生成列\"%s\"は設定できません"

#: plpy_exec.c:1026
>>>>>>> c1ff2d8bc5be55e302731a16aaff563b7f03ed7c
#, c-format
msgid "while modifying trigger row"
msgstr "トリガ行を変更する際に"

<<<<<<< HEAD
#: plpy_exec.c:1072
=======
#: plpy_exec.c:1087
>>>>>>> c1ff2d8bc5be55e302731a16aaff563b7f03ed7c
#, c-format
msgid "forcibly aborting a subtransaction that has not been exited"
msgstr "終了していないサブトランザクションを強制的にアボートしています"

#: plpy_main.c:125
#, c-format
msgid "multiple Python libraries are present in session"
msgstr "セッションに複数の Python ライブラリが存在します"

#: plpy_main.c:126
#, c-format
msgid "Only one Python major version can be used in one session."
<<<<<<< HEAD
msgstr "１個のセッション中で使える Python のメジャーバージョンは１種類だけです。"
=======
msgstr "1個のセッション中で使えるPythonのメジャーバージョンは1種類だけです。"
>>>>>>> c1ff2d8bc5be55e302731a16aaff563b7f03ed7c

#: plpy_main.c:142
#, c-format
msgid "untrapped error in initialization"
msgstr "初期化中に捕捉できないエラーがありました"

#: plpy_main.c:165
#, c-format
msgid "could not import \"__main__\" module"
msgstr "\"__main__\" モジュールをインポートできませんでした"

#: plpy_main.c:174
#, c-format
msgid "could not initialize globals"
msgstr "グローバル変数(globals)を初期化できませんでした"

#: plpy_main.c:399
#, c-format
msgid "PL/Python procedure \"%s\""
<<<<<<< HEAD
msgstr "PL/Python プロシージャ \"%s\""
=======
msgstr "PL/Pythonプロシージャ\"%s\""
>>>>>>> c1ff2d8bc5be55e302731a16aaff563b7f03ed7c

#: plpy_main.c:402
#, c-format
msgid "PL/Python function \"%s\""
msgstr "PL/Python関数\"%s\""

#: plpy_main.c:410
#, c-format
msgid "PL/Python anonymous code block"
msgstr "PL/Pythonの無名コードブロック"

<<<<<<< HEAD
#: plpy_plpymodule.c:192 plpy_plpymodule.c:195
=======
#: plpy_plpymodule.c:186 plpy_plpymodule.c:189
>>>>>>> c1ff2d8bc5be55e302731a16aaff563b7f03ed7c
#, c-format
msgid "could not import \"plpy\" module"
msgstr "\"plpy\"モジュールをインポートできませんでした"

<<<<<<< HEAD
#: plpy_plpymodule.c:210
=======
#: plpy_plpymodule.c:204
>>>>>>> c1ff2d8bc5be55e302731a16aaff563b7f03ed7c
#, c-format
msgid "could not create the spiexceptions module"
msgstr "spiexceptionsモジュールを生成できませんでした"

<<<<<<< HEAD
#: plpy_plpymodule.c:218
=======
#: plpy_plpymodule.c:212
>>>>>>> c1ff2d8bc5be55e302731a16aaff563b7f03ed7c
#, c-format
msgid "could not add the spiexceptions module"
msgstr "spiexceptionsモジュールを追加できませんでした"

<<<<<<< HEAD
#: plpy_plpymodule.c:286
=======
#: plpy_plpymodule.c:280
>>>>>>> c1ff2d8bc5be55e302731a16aaff563b7f03ed7c
#, c-format
msgid "could not generate SPI exceptions"
msgstr "SPI例外を生成できませんでした"

<<<<<<< HEAD
#: plpy_plpymodule.c:454
=======
#: plpy_plpymodule.c:448
>>>>>>> c1ff2d8bc5be55e302731a16aaff563b7f03ed7c
#, c-format
msgid "could not unpack arguments in plpy.elog"
msgstr "plpy.elogで引数を展開できませんでした"

<<<<<<< HEAD
#: plpy_plpymodule.c:463
=======
#: plpy_plpymodule.c:457
>>>>>>> c1ff2d8bc5be55e302731a16aaff563b7f03ed7c
msgid "could not parse error message in plpy.elog"
msgstr "plpy.elogでエラーメッセージをパースできませんでした"

<<<<<<< HEAD
#: plpy_plpymodule.c:480
=======
#: plpy_plpymodule.c:474
>>>>>>> c1ff2d8bc5be55e302731a16aaff563b7f03ed7c
#, c-format
msgid "argument 'message' given by name and position"
msgstr "名前と位置で 'message' 引数が渡されました"

<<<<<<< HEAD
#: plpy_plpymodule.c:507
=======
#: plpy_plpymodule.c:501
>>>>>>> c1ff2d8bc5be55e302731a16aaff563b7f03ed7c
#, c-format
msgid "'%s' is an invalid keyword argument for this function"
msgstr "この関数に対して'%s'は無効なキーワード引数です"

<<<<<<< HEAD
#: plpy_plpymodule.c:518 plpy_plpymodule.c:524
=======
#: plpy_plpymodule.c:512 plpy_plpymodule.c:518
>>>>>>> c1ff2d8bc5be55e302731a16aaff563b7f03ed7c
#, c-format
msgid "invalid SQLSTATE code"
msgstr "無効なSQLSTATEコードです"

#: plpy_procedure.c:230
#, c-format
msgid "trigger functions can only be called as triggers"
msgstr "トリガー関数はトリガーとしてのみ呼び出せます"

#: plpy_procedure.c:234
#, c-format
msgid "PL/Python functions cannot return type %s"
msgstr "PL/Python関数は%s型を返せません"

#: plpy_procedure.c:312
#, c-format
msgid "PL/Python functions cannot accept type %s"
msgstr "PL/Python関数は%s型を受け付けられません"

#: plpy_procedure.c:402
#, c-format
msgid "could not compile PL/Python function \"%s\""
msgstr "PL/Python関数\"%s\"をコンパイルできませんでした"

#: plpy_procedure.c:405
#, c-format
msgid "could not compile anonymous PL/Python code block"
msgstr "PL/Python無名コードブロックをコンパイルできませんでした"

<<<<<<< HEAD
#: plpy_resultobject.c:150 plpy_resultobject.c:176 plpy_resultobject.c:202
=======
#: plpy_resultobject.c:121 plpy_resultobject.c:147 plpy_resultobject.c:173
>>>>>>> c1ff2d8bc5be55e302731a16aaff563b7f03ed7c
#, c-format
msgid "command did not produce a result set"
msgstr "コマンドは結果セットを生成しませんでした"

#: plpy_spi.c:60
#, c-format
msgid "second argument of plpy.prepare must be a sequence"
msgstr "plpy.prepareの第二引数はシーケンスでなければなりません"

#: plpy_spi.c:104
#, c-format
msgid "plpy.prepare: type name at ordinal position %d is not a string"
msgstr "plpy.prepare: %d 番目の型名が文字列ではありません"

#: plpy_spi.c:176
#, c-format
msgid "plpy.execute expected a query or a plan"
msgstr "plpy.execute は問い合わせもしくは実行計画を期待していました"

#: plpy_spi.c:195
#, c-format
msgid "plpy.execute takes a sequence as its second argument"
msgstr "plpy.execute は第二引数としてシーケンスを取ります"

#: plpy_spi.c:305
#, c-format
msgid "SPI_execute_plan failed: %s"
msgstr "SPI_execute_plan が失敗しました: %s"

#: plpy_spi.c:347
#, c-format
msgid "SPI_execute failed: %s"
msgstr "SPI_execute が失敗しました: %s"

#: plpy_subxactobject.c:97
#, c-format
msgid "this subtransaction has already been entered"
msgstr "すでにこのサブトランザクションの中に入っています"

#: plpy_subxactobject.c:103 plpy_subxactobject.c:161
#, c-format
msgid "this subtransaction has already been exited"
msgstr "このサブトランザクションからすでに抜けています"

#: plpy_subxactobject.c:155
#, c-format
msgid "this subtransaction has not been entered"
msgstr "このサブトランザクションには入っていません"

#: plpy_subxactobject.c:167
#, c-format
msgid "there is no subtransaction to exit from"
msgstr "抜けるべきサブトランザクションがありません"

#: plpy_typeio.c:591
#, c-format
msgid "could not import a module for Decimal constructor"
msgstr "Decimalコンストラクタのためのモジュールをインポートできませんでした"

#: plpy_typeio.c:595
#, c-format
msgid "no Decimal attribute in module"
msgstr "モジュールの中にDecimal属性が含まれていません"

#: plpy_typeio.c:601
#, c-format
msgid "conversion from numeric to Decimal failed"
msgstr "numericからDecimalへの変換に失敗しました"

<<<<<<< HEAD
#: plpy_typeio.c:908
=======
#: plpy_typeio.c:915
>>>>>>> c1ff2d8bc5be55e302731a16aaff563b7f03ed7c
#, c-format
msgid "could not create bytes representation of Python object"
msgstr "Pythonオブジェクトのバイト表現を生成できませんでした"

<<<<<<< HEAD
#: plpy_typeio.c:1056
=======
#: plpy_typeio.c:1063
>>>>>>> c1ff2d8bc5be55e302731a16aaff563b7f03ed7c
#, c-format
msgid "could not create string representation of Python object"
msgstr "Pythonオブジェクトの文字列表現を生成できませんでした"

<<<<<<< HEAD
#: plpy_typeio.c:1067
#, c-format
msgid "could not convert Python object into cstring: Python string representation appears to contain null bytes"
msgstr "Python オブジェクトを cstring に変換できませんでした：Python の文字列表現に null バイトが含まれているようです"

#: plpy_typeio.c:1176
=======
#: plpy_typeio.c:1074
#, c-format
msgid ""
"could not convert Python object into cstring: Python string representation "
"appears to contain null bytes"
msgstr ""
"Pythonオブジェクトをcstringに変換できませんでした: Pythonの文字列表現にnullバ"
"イトが含まれているようです"

#: plpy_typeio.c:1183
>>>>>>> c1ff2d8bc5be55e302731a16aaff563b7f03ed7c
#, c-format
msgid "number of array dimensions exceeds the maximum allowed (%d)"
msgstr "配列の次元数が制限値(%d)を超えています"

<<<<<<< HEAD
#: plpy_typeio.c:1180
=======
#: plpy_typeio.c:1187
>>>>>>> c1ff2d8bc5be55e302731a16aaff563b7f03ed7c
#, c-format
msgid "could not determine sequence length for function return value"
msgstr "関数の戻り値について、シーケンスの長さを決定できませんでした"

<<<<<<< HEAD
#: plpy_typeio.c:1183 plpy_typeio.c:1187
=======
#: plpy_typeio.c:1190 plpy_typeio.c:1194
>>>>>>> c1ff2d8bc5be55e302731a16aaff563b7f03ed7c
#, c-format
msgid "array size exceeds the maximum allowed"
msgstr "配列のサイズが制限値を超えています"

<<<<<<< HEAD
#: plpy_typeio.c:1213
#, c-format
msgid "return value of function with array return type is not a Python sequence"
msgstr "配列型を返す関数の戻り値が Python のシーケンスではありません"

#: plpy_typeio.c:1259
#, c-format
msgid "wrong length of inner sequence: has length %d, but %d was expected"
msgstr "内部シーケンスで長さが異常です：長さは %d ですが、期待する値は %d でした"

#: plpy_typeio.c:1261
=======
#: plpy_typeio.c:1220
#, c-format
msgid ""
"return value of function with array return type is not a Python sequence"
msgstr "配列型を返す関数の戻り値がPythonのシーケンスではありません"

#: plpy_typeio.c:1266
#, c-format
msgid "wrong length of inner sequence: has length %d, but %d was expected"
msgstr "内部シーケンスで長さが異常です: 長さは%dですが、期待する値は%dでした"

#: plpy_typeio.c:1268
>>>>>>> c1ff2d8bc5be55e302731a16aaff563b7f03ed7c
#, c-format
msgid "To construct a multidimensional array, the inner sequences must all have the same length."
msgstr "多次元配列を生成する場合、内部シーケンスはすべて同じ長さでなければなりません。"

<<<<<<< HEAD
#: plpy_typeio.c:1340
#, c-format
msgid "malformed record literal: \"%s\""
msgstr "不正な形式のレコードリテラルです: \"%s\""

#: plpy_typeio.c:1341
=======
#: plpy_typeio.c:1347
#, c-format
msgid "malformed record literal: \"%s\""
msgstr "不正な形式のレコードリテラル: \"%s\""

#: plpy_typeio.c:1348
>>>>>>> c1ff2d8bc5be55e302731a16aaff563b7f03ed7c
#, c-format
msgid "Missing left parenthesis."
msgstr "左括弧がありません。"

<<<<<<< HEAD
#: plpy_typeio.c:1342 plpy_typeio.c:1543
#, c-format
msgid "To return a composite type in an array, return the composite type as a Python tuple, e.g., \"[('foo',)]\"."
msgstr "複合型を配列に入れて返したい場合、 \"[('foo',)]\" のように複合型を Pythonのタプルとして返すようにしてください。"

#: plpy_typeio.c:1389
=======
#: plpy_typeio.c:1349 plpy_typeio.c:1550
#, c-format
msgid ""
"To return a composite type in an array, return the composite type as a "
"Python tuple, e.g., \"[('foo',)]\"."
msgstr ""
"複合型を配列に入れて返したい場合、 \"[('foo',)]\" のように複合型を Pythonのタ"
"プルとして返すようにしてください。"

#: plpy_typeio.c:1396
>>>>>>> c1ff2d8bc5be55e302731a16aaff563b7f03ed7c
#, c-format
msgid "key \"%s\" not found in mapping"
msgstr "マッピング上にキー\"%s\"が見つかりません"

<<<<<<< HEAD
#: plpy_typeio.c:1390
#, c-format
msgid "To return null in a column, add the value None to the mapping with the key named after the column."
msgstr "カラムに null を入れて返す場合、カラム名をキーとして値が None のエントリをマッピングに追加してください"

#: plpy_typeio.c:1443
=======
#: plpy_typeio.c:1397
#, c-format
msgid ""
"To return null in a column, add the value None to the mapping with the key "
"named after the column."
msgstr ""
"カラムにnullを入れて返す場合、カラム名をキーとして値がNoneのエントリをマッピ"
"ングに追加してください。"

#: plpy_typeio.c:1450
>>>>>>> c1ff2d8bc5be55e302731a16aaff563b7f03ed7c
#, c-format
msgid "length of returned sequence did not match number of columns in row"
msgstr "返されたシーケンスの長さが行のカラム数とマッチしませんでした"

<<<<<<< HEAD
#: plpy_typeio.c:1541
=======
#: plpy_typeio.c:1548
>>>>>>> c1ff2d8bc5be55e302731a16aaff563b7f03ed7c
#, c-format
msgid "attribute \"%s\" does not exist in Python object"
msgstr "属性\"%s\"がPythonオブジェクト中に存在しません"

<<<<<<< HEAD
#: plpy_typeio.c:1544
#, c-format
msgid "To return null in a column, let the returned object have an attribute named after column with value None."
msgstr "カラムに null を入れて返す場合、カラム名をキーとして値が None である属性を持つオブジェクトを返すようにしてください。"
=======
#: plpy_typeio.c:1551
#, c-format
msgid ""
"To return null in a column, let the returned object have an attribute named "
"after column with value None."
msgstr ""
"カラムにnullを入れて返す場合、カラム名をキーとして値がNoneである属性を持つオ"
"ブジェクトを返すようにしてください。"
>>>>>>> c1ff2d8bc5be55e302731a16aaff563b7f03ed7c

#: plpy_util.c:35
#, c-format
msgid "could not convert Python Unicode object to bytes"
msgstr "PythonのUnicodeオブジェクトをバイト列に変換できませんでした"

#: plpy_util.c:41
#, c-format
msgid "could not extract bytes from encoded string"
msgstr "エンコードされた文字列からバイト列を抽出できませんでした"

#~ msgid "could not create new dictionary"
#~ msgstr "新しい辞書を作れませんでした"

#~ msgid "could not create exception \"%s\""
#~ msgstr "例外 \"%s \"を作成できませんでした"

#~ msgid "could not create globals"
#~ msgstr "グローバル変数(globals)を作成できませんでした"

#~ msgid "could not create new dictionary while building trigger arguments"
#~ msgstr "トリガの引数を構成中、新しい辞書を生成できませんでした"
